34. Tab completion vs. sudo -- shell crash

If we enter this much of a command:

    sudo -i [ ls /home/jao/.dbus/ses

tab-completion runs into permission problems trying to do its work.

----------------------------------------------------------------------

47. Emacs in background doesn't work

- Run emacs
- Ctrl-Z

Goes to background, but bg and fg do not revive it.

Complete "help interaction" when this is working.

As of about June 9, job control works on the console, but emacs never
suspends, and in fact it is no longer owned by the marcel
process. Exiting marcel leaves emacs running.

----------------------------------------------------------------------

48. Syntax error in .marcel.py should be handled more gracefully

jao@cheese:~/git/marcel/test$ marcel
Traceback (most recent call last):
  File "/usr/lib/python3.7/runpy.py", line 193, in _run_module_as_main
    "__main__", mod_spec)
  File "/usr/lib/python3.7/runpy.py", line 85, in _run_code
    exec(code, run_globals)
  File "/home/jao/git/marcel/marcel/main.py", line 211, in <module>
    MAIN = Main()
  File "/home/jao/git/marcel/marcel/main.py", line 90, in __init__
    self.env = marcel.env.Environment(self.config)
  File "/home/jao/git/marcel/marcel/env.py", line 136, in __init__
    self.read_config(config_file)
  File "/home/jao/git/marcel/marcel/env.py", line 201, in read_config
    exec(config_source, self.namespace, locals)
  File "<string>", line 64
    cat = [ map (f: (f, f.readlines())) | expand 1 ]
                  ^
SyntaxError: invalid syntax

----------------------------------------------------------------------

58. Infinite loop in help

There was a typo in the HELP for ps:

HELP = '''
{L,wrap=F}ps [-u|--user [USER]] [-g|--group [GROUP}] [-p|--pid PID] [-c|--command STRING]

Note that GROUP is followed by } instead of ]. That seemed to put 
help into an infinite loop.
----------------------------------------------------------------------

66. Parsing error due to whitespace

M-0.9.15 jao@cheese:~/git/marcel$ gen 3 | map(x: x+1)
Error: Running map(lambda: f'''map{x: x+1}''') on (0,): <lambda>() takes 0 positional arguments but 1 was given
Error: Running map(lambda: f'''map{x: x+1}''') on (1,): <lambda>() takes 0 positional arguments but 1 was given
Error: Running map(lambda: f'''map{x: x+1}''') on (2,): <lambda>() takes 0 positional arguments but 1 was given

Lexer.consolidate_tokens consolidates map and (...

IS THIS A BUG?

----------------------------------------------------------------------

67. Pipeline syntax needs to be generalized

    M-0.9.15 jao@cheese:~/git/marcel$ gen 3 | map (x: x + 5)
    5
    6
    7
    M-0.9.15 jao@cheese:~/git/marcel$ gen 3 | [x: map (x + 5)]
    Parsing error at position 8 of "...gen 3 | [x: map (x + 5)]...": Unexpected token type: Begin([)

This syntax:

    ... | [ ... ]

is rejected by the parser, which means we can't have pipelines with
parameters as literals. Fix the parser.

----------------------------------------------------------------------

69. Shell crashes on bad first arg to loop

M-0.9.17 jao@cheese:~$ loop (10, 1) [select (x, f: x > 0) | emit | map (x, f: (x-1, f*x))]
Traceback (most recent call last):
  File "/usr/lib/python3.8/runpy.py", line 193, in _run_module_as_main
    return _run_code(code, main_globals, None,
  File "/usr/lib/python3.8/runpy.py", line 86, in _run_code
    exec(code, run_globals)
  File "/home/jao/git/marcel/marcel/main.py", line 271, in <module>
    MAIN.run()
  File "/home/jao/git/marcel/marcel/main.py", line 123, in run
    self.run_command(line)
  File "/home/jao/git/marcel/marcel/main.py", line 136, in run_command
    pipeline = parser.parse()
  File "/home/jao/git/marcel/marcel/parser.py", line 704, in parse
    return self.command()
  File "/home/jao/git/marcel/marcel/parser.py", line 710, in command
    return self.pipeline(None)
  File "/home/jao/git/marcel/marcel/parser.py", line 730, in pipeline
    op_sequence = Parser.ensure_sequence(self.op_sequence())
  File "/home/jao/git/marcel/marcel/parser.py", line 740, in op_sequence
    op_args = self.op_args()
  File "/home/jao/git/marcel/marcel/parser.py", line 761, in op_args
    op = self.create_op(op_token, arg_tokens)
  File "/home/jao/git/marcel/marcel/parser.py", line 824, in create_op
    op = self.create_op_builtin(op_token, arg_tokens)
  File "/home/jao/git/marcel/marcel/parser.py", line 852, in create_op_builtin
    args.append(x.value(self) if isinstance(x, Token) else x)
  File "/home/jao/git/marcel/marcel/parser.py", line 298, in value
    self._function = marcel.functionwrapper.FunctionWrapper(function=function,
  File "/home/jao/git/marcel/marcel/functionwrapper.py", line 56, in __init__
    self._globals = self._function.__globals__
AttributeError: 'tuple' object has no attribute '__globals__'

----------------------------------------------------------------------

79. less doesn't work

----------------------------------------------------------------------

85. Any env var can be deleted

Even important ones, like PROMPT. Some of them need to be protected.

----------------------------------------------------------------------

87. Assign pipeline without brackets

Should it be allowed? If not, this failure mode is pretty bad:

    M-0.10.8 jao@cheese:~/git/marcel/marcel/object$ g = gen 5
    M-0.10.8 jao@cheese:~/git/marcel/marcel/object$ (g)
    gen

The string "gen" is assigned and the rest is ignored.

----------------------------------------------------------------------

89. Be able to execute marcel script from inside marcel

Don't require use of host shell.
    
----------------------------------------------------------------------

95. emacs no longer working

Specific to root.

M-0.10.13 root@cheese:/media/backup/daily/2020.08.26# emacs
emacs: Could not open file: /dev/tty
Escaped command failed with exit code 1: emacs
None

----------------------------------------------------------------------

97. ... | args [n: sql 'insert ... values(%s) (n)' does, essentially, autocommit

The problem is that each invocation of the pipeline does sql setup, receive, receive_complete.

----------------------------------------------------------------------

99. Redirection doesn't work for executables

This works, putting a list of Files into x:

    ls > x

This does not work:

    date > x

Error message: Variable date is undefined.

----------------------------------------------------------------------

100. Space after tab-completed flag is missing

ls --r<tab>

should produce '--recursive '. The space is omitted.

----------------------------------------------------------------------

102. Set ops can't be applied to lists

And the lists can't be anywhere, not even deeply nested. The problem
is hashing, which is applied deeply, and may reach a list. Lists are
not hashable.

Comparison-based algorithms are out too, since, for example:

    >>> [1,2] < ['a']
    Traceback (most recent call last):
      File "<stdin>", line 1, in <module>
    TypeError: '<' not supported between instances of 'int' and 'str'

Hmm.
----------------------------------------------------------------------

106. Wrong error message

    p = [x: gen(x)]
    p

Error message is: 

    Error evaluating lambda x: lambda: x on None: <lambda>() missing 1 required positional argument: 'x'

Should be:

    Unbound pipeline parameters for ...

I think.

----------------------------------------------------------------------

108. quote_files is failing, but only through the API?!

This fails, in test_api:

    TEST.run(test=lambda: run(ls('/tmp/a', file=True) |
                              args(lambda files: bash(f'mv -t d {quote_files(files)}'), all=True)),
             verification=lambda: run(ls('d', file=True) | map(lambda f: f.name)),
             expected_out=['a file', "a file with a ' mark", 'a_file'])

the quoted files are messed up, mv -t d ... fails. The command passed to bash is:

    mv -t d '/tmp/a/a file' '/tmp/a/a file with a '"'"' mark' /tmp/a/a_file

But somehow the quote marks get escaped, I think. Test is disabled for now.

The equivalent test in test_ops succeeds!?!?!?!

----------------------------------------------------------------------

113. Farcel error reporting is broken

ls /nosuchfile: Generates an error
@jao [ls /nosuchfile]: Error message shows up as output (see test_api test_remote)

Need to review how errors and exceptions are reported from farcel.

----------------------------------------------------------------------

114. Ctrl-C doesn't clean up temp file

- gen 10000000 > x
- ctrl-c while it's running

The env var isn't there, but the temp file is.

FIXED

116. Why is this crashing?

M-0.10.24 jao@cheese:~/git/marcel$ ls marcel test | out | args [d: ls -fr (d) | ext py | map (f: (f, f.read().count('\n'))) | sort (f, n: n) | tail 10]
drwxr-xr-x   jao    jao        4096   2020 Oct 05 14:09:31   marcel
(op/sql.py, 245)
(op/window.py, 254)
(op/fork.py, 296)
(job.py, 305)
(main.py, 316)
(env.py, 336)
(argsparser.py, 493)
(core.py, 514)
(helpformatter.py, 568)
(parser.py, 1099)
-rw-r--r--   jao    jao         652   2020 May 10 15:41:11   marcel/__init__.py
Process Process-11:
Traceback (most recent call last):
  File "/usr/lib/python3.8/multiprocessing/process.py", line 315, in _bootstrap
    self.run()
  File "/usr/lib/python3.8/multiprocessing/process.py", line 108, in run
    self._target(*self._args, **self._kwargs)
  File "/home/jao/git/marcel/marcel/job.py", line 147, in run_command_in_child
    child_namespace_changes = command.execute(self.env)
  File "/home/jao/git/marcel/marcel/core.py", line 463, in execute
    self.pipeline.receive(None)
  File "/home/jao/git/marcel/marcel/core.py", line 396, in receive
    self.first_op.receive_input(x)
  File "/home/jao/git/marcel/marcel/core.py", line 193, in receive_input
    self.receive(None if x is None else
  File "/home/jao/git/marcel/marcel/op/ls.py", line 155, in receive
    self.visit(root, 0)
  File "/home/jao/git/marcel/marcel/op/ls.py", line 167, in visit
    self.visit(file, level + 1)
  File "/home/jao/git/marcel/marcel/op/ls.py", line 163, in visit
    self.send_path(root)
  File "/home/jao/git/marcel/marcel/op/ls.py", line 180, in send_path
    self.send(file)
  File "/home/jao/git/marcel/marcel/core.py", line 176, in send
    receiver.receive_input(x)
  File "/home/jao/git/marcel/marcel/core.py", line 193, in receive_input
    self.receive(None if x is None else
  File "/home/jao/git/marcel/marcel/op/out.py", line 124, in receive
    self.send(x)
  File "/home/jao/git/marcel/marcel/core.py", line 176, in send
    receiver.receive_input(x)
  File "/home/jao/git/marcel/marcel/core.py", line 193, in receive_input
    self.receive(None if x is None else
  File "/home/jao/git/marcel/marcel/op/args.py", line 78, in receive
    self.impl.receive(x)
  File "/home/jao/git/marcel/marcel/op/args.py", line 108, in receive
    self.generate_and_run_pipeline()
  File "/home/jao/git/marcel/marcel/op/args.py", line 145, in generate_and_run_pipeline
    marcel.core.Command(None, self.pipeline).execute(self.op.env())
  File "/home/jao/git/marcel/marcel/core.py", line 460, in execute
    self.pipeline.setup_1(env)
  File "/home/jao/git/marcel/marcel/core.py", line 374, in setup_1
    op.setup_1(env)
  File "/home/jao/git/marcel/marcel/op/runpipeline.py", line 36, in setup_1
    assert self.pipeline is None
AssertionError


Simplifying: This causes the crash too:

    ls marcel | args [d: ls -fr (d) | ext py ]

But this does not:

    ls marcel | args [d: ls -fr (d) ]

Even simpler:

    g = [n: gen (n)]
    gen 3 1 | args [n: g (n)]

The problem seems to be a pipeline var inside args.
----------------------------------------------------------------------

118. Invoking runpipeline inside args results in RecursionError

M-0.10.25 jao@cheese:~$ fact = [x: gen (x) 1 | args [n: gen (n) 1 | red * | map (f: (n, f))]]
M-0.10.25 jao@cheese:~$ fact (20)
(1, 1)
(2, 2)
(3, 6)
(4, 24)
(5, 120)
(6, 720)
(7, 5040)
(8, 40320)
(9, 362880)
(10, 3628800)
(11, 39916800)
(12, 479001600)
(13, 6227020800)
(14, 87178291200)
(15, 1307674368000)
(16, 20922789888000)
Cloning error: (<class 'RecursionError'>) maximum recursion depth exceeded while calling a Python object
Caught <class 'RecursionError'>: maximum recursion depth exceeded while calling a Python object


It looks like the pipeline SOURCE being copied by args keeps growing?!?!
